Workbook

Sheet Инструкция
B2: ГРАФИК ЗАКУПКИ И ДОСТАВКИ МТР ДЛЯ КРЕПЛЕНИЯ СКВАЖИН ЮГ-1, ЮГ-2, ЮГ-3
B3: Дата формирования: 15.09.2026. Логистическая схема унаследована из файла «График доставки цемента на скв. ГЕО-12».
B5: СОСТАВ КНИГИ
B6: Справочник | C6: Единая база модели: длительности 8 этапов поставки по категориям МТР, программа крепления скважин и номенклатура с объемами. Все листы считаются формулами от этого листа — правка здесь пересчитывает всю книгу.
B7: ЮГ-1 / ЮГ-2 / ЮГ-3 | C7: Подробный график по каждой скважине: по каждой номенклатуре — ед.изм., кол-во, дата потребности и сроки (начало/окончание) по каждому из 8 этапов закупки и доставки.
B8: СВОДНЫЙ ГРАФИК | C8: Диаграмма Ганта по всем 42 позициям (14 номенклатур х 3 скважины) с вертикальной линией по текущей дате. Линия окрашивается по статусу строки: зеленая — в графике, желтая — риск, красная — срыв графика.
B9: Сводная потребность | C9: Суммарный объем закупки по номенклатуре на три скважины, самая ранняя дата потребности и худший статус.
B11: ЛОГИКА РАСЧЕТА
B12: Дата потребности | C12: Дата операции по креплению минус 5 сут (МТР должен быть на скважине заблаговременно). Задается на листе «Справочник», блок 2.
B13: Требуемая дата старта | C13: Дата потребности минус суммарная длительность цикла закупки и доставки. Крайний срок размещения заказа.
B14: Дата начала (план/факт) | C14: Плановая дата размещения заказа. Принята как «требуемая дата старта минус 14 сут резерва», но не ранее 20.09.2026 (готовность закупочной процедуры). ЖЕЛТЫЕ ЯЧЕЙКИ — поле ввода: подставьте фактическую дату заключения договора, книга пересчитается.
B15: Прогноз поставки на скважину | C15: Дата начала (план/факт) + длительности всех 8 этапов последовательно.
B16: Запас, сут | C16: Дата потребности минус прогноз поставки. Отрицательное значение — опоздание.
B18: ЛЕГЕНДА СТАТУСОВ
B19: В ГРАФИКЕ | C19: Запас >= 14 сут. Поставка обеспечивает срок крепления.
B20: РИСК | C20: Запас от 0 до 13 сут. Резерв времени исчерпан, любая задержка ведет к срыву.
B21: СРЫВ ГРАФИКА | C21: Запас < 0. Прогнозная поставка позже даты потребности — требуются компенсирующие мероприятия.
B23: ПРИНЯТЫЕ ДОПУЩЕНИЯ (подлежат уточнению Заказчиком)
B24: Конструкция скважин | C24: Направление ОК-426 (0-50 м), кондуктор ОК-324 (0-500 м), эксплуатационная колонна ОК-245 (0-1800 м), хвостовик ОК-168 (1700-2500 м). Конструкция принята одинаковой для ЮГ-1, ЮГ-2, ЮГ-3.
B25: Программа бурения | C25: Скважины строятся последовательно одной буровой установкой со сдвигом 60 суток между скважинами. Даты операций по креплению — блок 2 листа «Справочник».
B26: Логистическая схема | C26: Завод-изготовитель (Тюмень/Урал) — ж/д до ст. Владивосток — перевалка на судно — морской переход до Петропавловска-Камчатского — доставка автотранспортом с базы Заказчика до куста. Длительности ж/д и морского плеча приняты по фактическим данным графика ГЕО-12.
B27: Объемы тампонажных материалов | C27: Расчет по кольцевому пространству с коэффициентом кавернозности 1,25-1,30 и запасом 10%. Подлежат уточнению после кавернометрии и утверждения плана работ по креплению.
B28: Труба обсадная ОК-168 | C28: В перечне заявлена тех.оснастка ОК-168 и разъединительный переводник 245/168, но сама труба ОК-168 не заявлена. Принято, что хвостовик 168 мм обеспечивается из давальческих запасов Заказчика. Требует подтверждения — при закупке добавить позицию в номенклатуру (блок 3 листа «Справочник»).
B29: Замедлитель | C29: Закупается единой партией на все этапы крепления скважины, дата потребности привязана к самой ранней операции (крепление направления).
B31: КРИТИЧЕСКИЕ ПОЗИЦИИ
B32: Что требует решения сейчас | C32: По скважине ЮГ-1 позиции с длинным циклом изготовления (трубы ОК-426 и ОК-324, тех.оснастка ОК-426) имеют отрицательный запас: крайний срок размещения заказа уже прошел относительно даты формирования графика. Компенсирующие мероприятия указаны в столбце «Примечание / мероприятия» на листе скважины и в сводном графике.

Sheet Справочник
A1: СПРАВОЧНИК ИСХОДНЫХ ДАННЫХ
A2: Единственное место ввода. Все графики по скважинам и сводный график пересчитываются формулами от этого листа.
A4: 1. ДЛИТЕЛЬНОСТЬ ЭТАПОВ ЗАКУПКИ И ДОСТАВКИ ПО КАТЕГОРИЯМ МТР, суток
A5: № | B5: Наименование этапа | C5: Тампонажные материалы (цементы, смеси) | D5: Химреагенты (замедлитель) | E5: Трубы обсадные | F5: Технологическая оснастка | G5: Спецоборудование (пакер, переводник)
A6: 1 | B6: Размещение заказа, заключение договора, согласование спецификации | C6: 10 | D6: 10 | E6: 14 | F6: 10 | G6: 14
A7: 2 | B7: Изготовление на заводе-изготовителе (для тампонажных материалов — приготовление и замес смеси) | C7: 3 | D7: 5 | E7: 35 | F7: 25 | G7: 60
A8: 3 | B8: Подготовка к отгрузке: растаривание/затарка в МКР, пакетирование, маркировка | C8: 2 | D8: 1 | E8: 2 | F8: 2 | G8: 2
A9: 4 | B9: Перевозка на контейнерный терминал, затарка в контейнеры, погрузка на ж/д | C9: 2 | D9: 1 | E9: 3 | F9: 2 | G9: 2
A10: 5 | B10: Перевозка ж/д транспортом (завод-изготовитель — ст. Владивосток) | C10: 14 | D10: 14 | E10: 18 | F10: 16 | G10: 16
A11: 6 | B11: Перевалка во Владивостоке на морское судно | C11: 2 | D11: 2 | E11: 3 | F11: 2 | G11: 2
A12: 7 | B12: Морской переход Владивосток — Петропавловск-Камчатский | C12: 7 | D12: 7 | E12: 7 | F12: 7 | G12: 7
A13: 8 | B13: Доставка с базы Заказчика в г. Петропавловск-Камчатский до скважины | C13: 4 | D13: 4 | E13: 5 | F13: 4 | G13: 4
B14: ИТОГО длительность цикла, суток | C14: =SUM(C6:C13) | D14: =SUM(D6:D13) | E14: =SUM(E6:E13) | F14: =SUM(F6:F13) | G14: =SUM(G6:G13)
A16: 2. ПРОГРАММА КРЕПЛЕНИЯ СКВАЖИН И ДАТЫ ПОТРЕБНОСТИ МТР
A17: № | B17: Скважина / этап крепления | C17: Дата операции по ГТН | D17: Заблаговр., сут | E17: ДАТА ПОТРЕБНОСТИ (МТР на скважине)
A18: 1 | B18: ЮГ-1 — Направление ОК-426 | C18: 46346 | D18: 5 | E18: =C18-D18
A19: 2 | B19: ЮГ-1 — Кондуктор ОК-324 | C19: 46361 | D19: 5 | E19: =C19-D19
A20: 3 | B20: ЮГ-1 — Экспл. колонна ОК-245 | C20: 46392 | D20: 5 | E20: =C20-D20
A21: 4 | B21: ЮГ-1 — Хвостовик ОК-168 | C21: 46407 | D21: 5 | E21: =C21-D21
A22: 5 | B22: ЮГ-2 — Направление ОК-426 | C22: 46406 | D22: 5 | E22: =C22-D22
A23: 6 | B23: ЮГ-2 — Кондуктор ОК-324 | C23: 46421 | D23: 5 | E23: =C23-D23
A24: 7 | B24: ЮГ-2 — Экспл. колонна ОК-245 | C24: 46452 | D24: 5 | E24: =C24-D24
A25: 8 | B25: ЮГ-2 — Хвостовик ОК-168 | C25: 46467 | D25: 5 | E25: =C25-D25
A26: 9 | B26: ЮГ-3 — Направление ОК-426 | C26: 46466 | D26: 5 | E26: =C26-D26
A27: 10 | B27: ЮГ-3 — Кондуктор ОК-324 | C27: 46481 | D27: 5 | E27: =C27-D27
A28: 11 | B28: ЮГ-3 — Экспл. колонна ОК-245 | C28: 46512 | D28: 5 | E28: =C28-D28
A29: 12 | B29: ЮГ-3 — Хвостовик ОК-168 | C29: 46527 | D29: 5 | E29: =C29-D29
A31: 3. НОМЕНКЛАТУРА И ОБЪЕМЫ ЗАКУПКИ
A32: № | B32: Наименование МТР | C32: Ед. изм. | D32: Категория поставки | E32: Этап крепления | F32: ЮГ-1 | G32: ЮГ-2 | H32: ЮГ-3 | I32: ИТОГО | J32: Обоснование объема / характеристика
A33: 1 | B33: Цемент марки G (направление) | C33: т | D33: Тампонажные материалы (цементы, смеси) | E33: Направление ОК-426 | F33: 15 | G33: 15 | H33: 15 | I33: =SUM(F33:H33) | J33: ПЦТ G HSR. Расчет: кольцевое пространство 590/426 мм, 0-50 м + стакан, к-т каверн. 1,3, запас 10%
A34: 2 | B34: Цементная смесь тяжелая (кондуктор) | C34: т | D34: Тампонажные материалы (цементы, смеси) | E34: Кондуктор ОК-324 | F34: 50 | G34: 50 | H34: 50 | I34: =SUM(F34:H34) | J34: ρ=1,85 г/см3. Кольцевое пространство 393,7/324 мм, 0-500 м, к-т каверн. 1,3, запас 10%
A35: 3 | B35: Цементная смесь тяжелая (экспл.колонна) | C35: т | D35: Тампонажные материалы (цементы, смеси) | E35: Экспл. колонна ОК-245 | F35: 32 | G35: 32 | H35: 32 | I35: =SUM(F35:H35) | J35: ρ=1,85 г/см3. Нижняя ступень 1200-1800 м, кольц. пр-во 295,3/245 мм, к-т каверн. 1,25
A36: 4 | B36: Цементная смесь легкая (экспл.колонна) | C36: т | D36: Тампонажные материалы (цементы, смеси) | E36: Экспл. колонна ОК-245 | F36: 45 | G36: 45 | H36: 45 | I36: =SUM(F36:H36) | J36: ρ=1,50 г/см3. Верхняя ступень 0-1200 м, кольц. пр-во 295,3/245 мм, к-т каверн. 1,25
A37: 5 | B37: Замедлитель | C37: кг | D37: Химреагенты (замедлитель) | E37: Направление ОК-426 | F37: 600 | G37: 600 | H37: 600 | I37: =SUM(F37:H37) | J37: Термостойкий замедлитель схватывания, 0,4% от массы цемента (142 т). Поставка единой партией под все этапы крепления
A38: 6 | B38: Труба обсадная ОК-426 | C38: м | D38: Трубы обсадные | E38: Направление ОК-426 | F38: 60 | G38: 60 | H38: 60 | I38: =SUM(F38:H38) | J38: 426х10 мм, гр.пр. Д, резьба ОТТМ. Глубина спуска 50 м + технологический запас
A39: 7 | B39: Труба обсадная ОК-324 | C39: м | D39: Трубы обсадные | E39: Кондуктор ОК-324 | F39: 520 | G39: 520 | H39: 520 | I39: =SUM(F39:H39) | J39: 324х9,5 мм, гр.пр. Д, резьба ОТТМ. Глубина спуска 500 м + технологический запас
A40: 8 | B40: Труба обсадная ОК-245 | C40: м | D40: Трубы обсадные | E40: Экспл. колонна ОК-245 | F40: 1830 | G40: 1830 | H40: 1830 | I40: =SUM(F40:H40) | J40: 245х10 мм, гр.пр. Е, резьба ОТТГ. Глубина спуска 1800 м + технологический запас
A41: 9 | B41: Тех.оснастка (ОК-426) | C41: компл. | D41: Технологическая оснастка | E41: Направление ОК-426 | F41: 1 | G41: 1 | H41: 1 | I41: =SUM(F41:H41) | J41: Башмак БКМ-426, ЦКОД-426, центраторы ЦЦ-426/590 - 5 шт, пробка продавочная ПП-426
A42: 10 | B42: Тех.оснастка (ОК-324) | C42: компл. | D42: Технологическая оснастка | E42: Кондуктор ОК-324 | F42: 1 | G42: 1 | H42: 1 | I42: =SUM(F42:H42) | J42: Башмак БКМ-324, ЦКОД-324, центраторы ЦЦ-324/394 - 25 шт, ЦТ, пробка продавочная ПП-324
A43: 11 | B43: Тех.оснастка (ОК-245) | C43: компл. | D43: Технологическая оснастка | E43: Экспл. колонна ОК-245 | F43: 1 | G43: 1 | H43: 1 | I43: =SUM(F43:H43) | J43: Башмак БКМ-245, ЦКОД-245, МСЦ-245, центраторы ЦЦ-245/295 - 60 шт, пробки продавочные
...

Sheet ЮГ-1
A1: ГРАФИК ЗАКУПКИ И ДОСТАВКИ МТР ДЛЯ КРЕПЛЕНИЯ СКВАЖИНЫ ЮГ-1
A2: Дата формирования 15.09.2026. Даты потребности и длительности этапов — с листа «Справочник». Желтые ячейки (столбец J) — ввод фактической даты размещения заказа. Группировка слева сворачивает этапы.
A4: № | B4: Наименование МТР / этапа закупки и доставки | C4: Ед. изм. | D4: Кол-во | E4: Длит., сут | F4: Начало этапа | G4: Окончание этапа | H4: ДАТА ПОТРЕБНОСТИ | I4: Требуемая дата старта | J4: Дата начала (план/факт) | K4: Прогноз поставки на скважину | L4: Запас, сут | M4: СТАТУС | N4: Примечание / компенсирующие мероприятия
A5: 1 | B5: Цемент марки G (направление) | C5: =Справочник!$C$33 | D5: =Справочник!$F$33 | E5: =SUM(E6:E13) | F5: Этап крепления: Направление ОК-426 | H5: =Справочник!$E$18 | I5: =H5-E5 | J5: 46285 | K5: =G13 | L5: =H5-K5 | M5: =IF(L5<0,"СРЫВ ГРАФИКА",IF(L5<14,"РИСК","В ГРАФИКЕ")) | N5: Запас 12 сут — ниже норматива 14 сут. Заказ разместить первым приоритетом, взять на еженедельный контроль.
A6: 1 | B6: =Справочник!$B$6 | E6: =Справочник!$C$6 | F6: =J5 | G6: =F6+E6
A7: 2 | B7: =Справочник!$B$7 | E7: =Справочник!$C$7 | F7: =G6 | G7: =F7+E7
A8: 3 | B8: =Справочник!$B$8 | E8: =Справочник!$C$8 | F8: =G7 | G8: =F8+E8
A9: 4 | B9: =Справочник!$B$9 | E9: =Справочник!$C$9 | F9: =G8 | G9: =F9+E9
A10: 5 | B10: =Справочник!$B$10 | E10: =Справочник!$C$10 | F10: =G9 | G10: =F10+E10
A11: 6 | B11: =Справочник!$B$11 | E11: =Справочник!$C$11 | F11: =G10 | G11: =F11+E11
A12: 7 | B12: =Справочник!$B$12 | E12: =Справочник!$C$12 | F12: =G11 | G12: =F12+E12
A13: 8 | B13: =Справочник!$B$13 | E13: =Справочник!$C$13 | F13: =G12 | G13: =F13+E13
A15: 2 | B15: Цементная смесь тяжелая (кондуктор) | C15: =Справочник!$C$34 | D15: =Справочник!$F$34 | E15: =SUM(E16:E23) | F15: Этап крепления: Кондуктор ОК-324 | H15: =Справочник!$E$19 | I15: =H15-E15 | J15: 46298 | K15: =G23 | L15: =H15-K15 | M15: =IF(L15<0,"СРЫВ ГРАФИКА",IF(L15<14,"РИСК","В ГРАФИКЕ"))
A16: 1 | B16: =Справочник!$B$6 | E16: =Справочник!$C$6 | F16: =J15 | G16: =F16+E16
A17: 2 | B17: =Справочник!$B$7 | E17: =Справочник!$C$7 | F17: =G16 | G17: =F17+E17
A18: 3 | B18: =Справочник!$B$8 | E18: =Справочник!$C$8 | F18: =G17 | G18: =F18+E18
A19: 4 | B19: =Справочник!$B$9 | E19: =Справочник!$C$9 | F19: =G18 | G19: =F19+E19
A20: 5 | B20: =Справочник!$B$10 | E20: =Справочник!$C$10 | F20: =G19 | G20: =F20+E20
A21: 6 | B21: =Справочник!$B$11 | E21: =Справочник!$C$11 | F21: =G20 | G21: =F21+E21
A22: 7 | B22: =Справочник!$B$12 | E22: =Справочник!$C$12 | F22: =G21 | G22: =F22+E22
A23: 8 | B23: =Справочник!$B$13 | E23: =Справочник!$C$13 | F23: =G22 | G23: =F23+E23
A25: 3 | B25: Цементная смесь тяжелая (экспл.колонна) | C25: =Справочник!$C$35 | D25: =Справочник!$F$35 | E25: =SUM(E26:E33) | F25: Этап крепления: Экспл. колонна ОК-245 | H25: =Справочник!$E$20 | I25: =H25-E25 | J25: 46329 | K25: =G33 | L25: =H25-K25 | M25: =IF(L25<0,"СРЫВ ГРАФИКА",IF(L25<14,"РИСК","В ГРАФИКЕ"))
A26: 1 | B26: =Справочник!$B$6 | E26: =Справочник!$C$6 | F26: =J25 | G26: =F26+E26
A27: 2 | B27: =Справочник!$B$7 | E27: =Справочник!$C$7 | F27: =G26 | G27: =F27+E27
A28: 3 | B28: =Справочник!$B$8 | E28: =Справочник!$C$8 | F28: =G27 | G28: =F28+E28
A29: 4 | B29: =Справочник!$B$9 | E29: =Справочник!$C$9 | F29: =G28 | G29: =F29+E29
A30: 5 | B30: =Справочник!$B$10 | E30: =Справочник!$C$10 | F30: =G29 | G30: =F30+E30
A31: 6 | B31: =Справочник!$B$11 | E31: =Справочник!$C$11 | F31: =G30 | G31: =F31+E31
A32: 7 | B32: =Справочник!$B$12 | E32: =Справочник!$C$12 | F32: =G31 | G32: =F32+E32
A33: 8 | B33: =Справочник!$B$13 | E33: =Справочник!$C$13 | F33: =G32 | G33: =F33+E33
A35: 4 | B35: Цементная смесь легкая (экспл.колонна) | C35: =Справочник!$C$36 | D35: =Справочник!$F$36 | E35: =SUM(E36:E43) | F35: Этап крепления: Экспл. колонна ОК-245 | H35: =Справочник!$E$20 | I35: =H35-E35 | J35: 46329 | K35: =G43 | L35: =H35-K35 | M35: =IF(L35<0,"СРЫВ ГРАФИКА",IF(L35<14,"РИСК","В ГРАФИКЕ"))
A36: 1 | B36: =Справочник!$B$6 | E36: =Справочник!$C$6 | F36: =J35 | G36: =F36+E36
A37: 2 | B37: =Справочник!$B$7 | E37: =Справочник!$C$7 | F37: =G36 | G37: =F37+E37
A38: 3 | B38: =Справочник!$B$8 | E38: =Справочник!$C$8 | F38: =G37 | G38: =F38+E38
A39: 4 | B39: =Справочник!$B$9 | E39: =Справочник!$C$9 | F39: =G38 | G39: =F39+E39
A40: 5 | B40: =Справочник!$B$10 | E40: =Справочник!$C$10 | F40: =G39 | G40: =F40+E40
A41: 6 | B41: =Справочник!$B$11 | E41: =Справочник!$C$11 | F41: =G40 | G41: =F41+E41
A42: 7 | B42: =Справочник!$B$12 | E42: =Справочник!$C$12 | F42: =G41 | G42: =F42+E42
A43: 8 | B43: =Справочник!$B$13 | E43: =Справочник!$C$13 | F43: =G42 | G43: =F43+E43
A45: 5 | B45: Замедлитель | C45: =Справочник!$C$37 | D45: =Справочник!$F$37 | E45: =SUM(E46:E53) | F45: Этап крепления: Направление ОК-426 | H45: =Справочник!$E$18 | I45: =H45-E45 | J45: 46285 | K45: =G53 | L45: =H45-K45 | M45: =IF(L45<0,"СРЫВ ГРАФИКА",IF(L45<14,"РИСК","В ГРАФИКЕ")) | N45: Запас 12 сут — ниже норматива 14 сут. Заказ разместить первым приоритетом, взять на еженедельный контроль.
...

Sheet ЮГ-2
A1: ГРАФИК ЗАКУПКИ И ДОСТАВКИ МТР ДЛЯ КРЕПЛЕНИЯ СКВАЖИНЫ ЮГ-2
A2: Дата формирования 15.09.2026. Даты потребности и длительности этапов — с листа «Справочник». Желтые ячейки (столбец J) — ввод фактической даты размещения заказа. Группировка слева сворачивает этапы.
A4: № | B4: Наименование МТР / этапа закупки и доставки | C4: Ед. изм. | D4: Кол-во | E4: Длит., сут | F4: Начало этапа | G4: Окончание этапа | H4: ДАТА ПОТРЕБНОСТИ | I4: Требуемая дата старта | J4: Дата начала (план/факт) | K4: Прогноз поставки на скважину | L4: Запас, сут | M4: СТАТУС | N4: Примечание / компенсирующие мероприятия
A5: 1 | B5: Цемент марки G (направление) | C5: =Справочник!$C$33 | D5: =Справочник!$G$33 | E5: =SUM(E6:E13) | F5: Этап крепления: Направление ОК-426 | H5: =Справочник!$E$22 | I5: =H5-E5 | J5: 46343 | K5: =G13 | L5: =H5-K5 | M5: =IF(L5<0,"СРЫВ ГРАФИКА",IF(L5<14,"РИСК","В ГРАФИКЕ"))
A6: 1 | B6: =Справочник!$B$6 | E6: =Справочник!$C$6 | F6: =J5 | G6: =F6+E6
A7: 2 | B7: =Справочник!$B$7 | E7: =Справочник!$C$7 | F7: =G6 | G7: =F7+E7
A8: 3 | B8: =Справочник!$B$8 | E8: =Справочник!$C$8 | F8: =G7 | G8: =F8+E8
A9: 4 | B9: =Справочник!$B$9 | E9: =Справочник!$C$9 | F9: =G8 | G9: =F9+E9
A10: 5 | B10: =Справочник!$B$10 | E10: =Справочник!$C$10 | F10: =G9 | G10: =F10+E10
A11: 6 | B11: =Справочник!$B$11 | E11: =Справочник!$C$11 | F11: =G10 | G11: =F11+E11
A12: 7 | B12: =Справочник!$B$12 | E12: =Справочник!$C$12 | F12: =G11 | G12: =F12+E12
A13: 8 | B13: =Справочник!$B$13 | E13: =Справочник!$C$13 | F13: =G12 | G13: =F13+E13
A15: 2 | B15: Цементная смесь тяжелая (кондуктор) | C15: =Справочник!$C$34 | D15: =Справочник!$G$34 | E15: =SUM(E16:E23) | F15: Этап крепления: Кондуктор ОК-324 | H15: =Справочник!$E$23 | I15: =H15-E15 | J15: 46358 | K15: =G23 | L15: =H15-K15 | M15: =IF(L15<0,"СРЫВ ГРАФИКА",IF(L15<14,"РИСК","В ГРАФИКЕ"))
A16: 1 | B16: =Справочник!$B$6 | E16: =Справочник!$C$6 | F16: =J15 | G16: =F16+E16
A17: 2 | B17: =Справочник!$B$7 | E17: =Справочник!$C$7 | F17: =G16 | G17: =F17+E17
A18: 3 | B18: =Справочник!$B$8 | E18: =Справочник!$C$8 | F18: =G17 | G18: =F18+E18
A19: 4 | B19: =Справочник!$B$9 | E19: =Справочник!$C$9 | F19: =G18 | G19: =F19+E19
A20: 5 | B20: =Справочник!$B$10 | E20: =Справочник!$C$10 | F20: =G19 | G20: =F20+E20
A21: 6 | B21: =Справочник!$B$11 | E21: =Справочник!$C$11 | F21: =G20 | G21: =F21+E21
A22: 7 | B22: =Справочник!$B$12 | E22: =Справочник!$C$12 | F22: =G21 | G22: =F22+E22
A23: 8 | B23: =Справочник!$B$13 | E23: =Справочник!$C$13 | F23: =G22 | G23: =F23+E23
A25: 3 | B25: Цементная смесь тяжелая (экспл.колонна) | C25: =Справочник!$C$35 | D25: =Справочник!$G$35 | E25: =SUM(E26:E33) | F25: Этап крепления: Экспл. колонна ОК-245 | H25: =Справочник!$E$24 | I25: =H25-E25 | J25: 46389 | K25: =G33 | L25: =H25-K25 | M25: =IF(L25<0,"СРЫВ ГРАФИКА",IF(L25<14,"РИСК","В ГРАФИКЕ"))
A26: 1 | B26: =Справочник!$B$6 | E26: =Справочник!$C$6 | F26: =J25 | G26: =F26+E26
A27: 2 | B27: =Справочник!$B$7 | E27: =Справочник!$C$7 | F27: =G26 | G27: =F27+E27
A28: 3 | B28: =Справочник!$B$8 | E28: =Справочник!$C$8 | F28: =G27 | G28: =F28+E28
A29: 4 | B29: =Справочник!$B$9 | E29: =Справочник!$C$9 | F29: =G28 | G29: =F29+E29
A30: 5 | B30: =Справочник!$B$10 | E30: =Справочник!$C$10 | F30: =G29 | G30: =F30+E30
A31: 6 | B31: =Справочник!$B$11 | E31: =Справочник!$C$11 | F31: =G30 | G31: =F31+E31
A32: 7 | B32: =Справочник!$B$12 | E32: =Справочник!$C$12 | F32: =G31 | G32: =F32+E32
A33: 8 | B33: =Справочник!$B$13 | E33: =Справочник!$C$13 | F33: =G32 | G33: =F33+E33
A35: 4 | B35: Цементная смесь легкая (экспл.колонна) | C35: =Справочник!$C$36 | D35: =Справочник!$G$36 | E35: =SUM(E36:E43) | F35: Этап крепления: Экспл. колонна ОК-245 | H35: =Справочник!$E$24 | I35: =H35-E35 | J35: 46389 | K35: =G43 | L35: =H35-K35 | M35: =IF(L35<0,"СРЫВ ГРАФИКА",IF(L35<14,"РИСК","В ГРАФИКЕ"))
A36: 1 | B36: =Справочник!$B$6 | E36: =Справочник!$C$6 | F36: =J35 | G36: =F36+E36
A37: 2 | B37: =Справочник!$B$7 | E37: =Справочник!$C$7 | F37: =G36 | G37: =F37+E37
A38: 3 | B38: =Справочник!$B$8 | E38: =Справочник!$C$8 | F38: =G37 | G38: =F38+E38
A39: 4 | B39: =Справочник!$B$9 | E39: =Справочник!$C$9 | F39: =G38 | G39: =F39+E39
A40: 5 | B40: =Справочник!$B$10 | E40: =Справочник!$C$10 | F40: =G39 | G40: =F40+E40
A41: 6 | B41: =Справочник!$B$11 | E41: =Справочник!$C$11 | F41: =G40 | G41: =F41+E41
A42: 7 | B42: =Справочник!$B$12 | E42: =Справочник!$C$12 | F42: =G41 | G42: =F42+E42
A43: 8 | B43: =Справочник!$B$13 | E43: =Справочник!$C$13 | F43: =G42 | G43: =F43+E43
A45: 5 | B45: Замедлитель | C45: =Справочник!$C$37 | D45: =Справочник!$G$37 | E45: =SUM(E46:E53) | F45: Этап крепления: Направление ОК-426 | H45: =Справочник!$E$22 | I45: =H45-E45 | J45: 46343 | K45: =G53 | L45: =H45-K45 | M45: =IF(L45<0,"СРЫВ ГРАФИКА",IF(L45<14,"РИСК","В ГРАФИКЕ"))
...

Sheet ЮГ-3
A1: ГРАФИК ЗАКУПКИ И ДОСТАВКИ МТР ДЛЯ КРЕПЛЕНИЯ СКВАЖИНЫ ЮГ-3
A2: Дата формирования 15.09.2026. Даты потребности и длительности этапов — с листа «Справочник». Желтые ячейки (столбец J) — ввод фактической даты размещения заказа. Группировка слева сворачивает этапы.
A4: № | B4: Наименование МТР / этапа закупки и доставки | C4: Ед. изм. | D4: Кол-во | E4: Длит., сут | F4: Начало этапа | G4: Окончание этапа | H4: ДАТА ПОТРЕБНОСТИ | I4: Требуемая дата старта | J4: Дата начала (план/факт) | K4: Прогноз поставки на скважину | L4: Запас, сут | M4: СТАТУС | N4: Примечание / компенсирующие мероприятия
A5: 1 | B5: Цемент марки G (направление) | C5: =Справочник!$C$33 | D5: =Справочник!$H$33 | E5: =SUM(E6:E13) | F5: Этап крепления: Направление ОК-426 | H5: =Справочник!$E$26 | I5: =H5-E5 | J5: 46403 | K5: =G13 | L5: =H5-K5 | M5: =IF(L5<0,"СРЫВ ГРАФИКА",IF(L5<14,"РИСК","В ГРАФИКЕ"))
A6: 1 | B6: =Справочник!$B$6 | E6: =Справочник!$C$6 | F6: =J5 | G6: =F6+E6
A7: 2 | B7: =Справочник!$B$7 | E7: =Справочник!$C$7 | F7: =G6 | G7: =F7+E7
A8: 3 | B8: =Справочник!$B$8 | E8: =Справочник!$C$8 | F8: =G7 | G8: =F8+E8
A9: 4 | B9: =Справочник!$B$9 | E9: =Справочник!$C$9 | F9: =G8 | G9: =F9+E9
A10: 5 | B10: =Справочник!$B$10 | E10: =Справочник!$C$10 | F10: =G9 | G10: =F10+E10
A11: 6 | B11: =Справочник!$B$11 | E11: =Справочник!$C$11 | F11: =G10 | G11: =F11+E11
A12: 7 | B12: =Справочник!$B$12 | E12: =Справочник!$C$12 | F12: =G11 | G12: =F12+E12
A13: 8 | B13: =Справочник!$B$13 | E13: =Справочник!$C$13 | F13: =G12 | G13: =F13+E13
A15: 2 | B15: Цементная смесь тяжелая (кондуктор) | C15: =Справочник!$C$34 | D15: =Справочник!$H$34 | E15: =SUM(E16:E23) | F15: Этап крепления: Кондуктор ОК-324 | H15: =Справочник!$E$27 | I15: =H15-E15 | J15: 46418 | K15: =G23 | L15: =H15-K15 | M15: =IF(L15<0,"СРЫВ ГРАФИКА",IF(L15<14,"РИСК","В ГРАФИКЕ"))
A16: 1 | B16: =Справочник!$B$6 | E16: =Справочник!$C$6 | F16: =J15 | G16: =F16+E16
A17: 2 | B17: =Справочник!$B$7 | E17: =Справочник!$C$7 | F17: =G16 | G17: =F17+E17
A18: 3 | B18: =Справочник!$B$8 | E18: =Справочник!$C$8 | F18: =G17 | G18: =F18+E18
A19: 4 | B19: =Справочник!$B$9 | E19: =Справочник!$C$9 | F19: =G18 | G19: =F19+E19
A20: 5 | B20: =Справочник!$B$10 | E20: =Справочник!$C$10 | F20: =G19 | G20: =F20+E20
A21: 6 | B21: =Справочник!$B$11 | E21: =Справочник!$C$11 | F21: =G20 | G21: =F21+E21
A22: 7 | B22: =Справочник!$B$12 | E22: =Справочник!$C$12 | F22: =G21 | G22: =F22+E22
A23: 8 | B23: =Справочник!$B$13 | E23: =Справочник!$C$13 | F23: =G22 | G23: =F23+E23
A25: 3 | B25: Цементная смесь тяжелая (экспл.колонна) | C25: =Справочник!$C$35 | D25: =Справочник!$H$35 | E25: =SUM(E26:E33) | F25: Этап крепления: Экспл. колонна ОК-245 | H25: =Справочник!$E$28 | I25: =H25-E25 | J25: 46449 | K25: =G33 | L25: =H25-K25 | M25: =IF(L25<0,"СРЫВ ГРАФИКА",IF(L25<14,"РИСК","В ГРАФИКЕ"))
A26: 1 | B26: =Справочник!$B$6 | E26: =Справочник!$C$6 | F26: =J25 | G26: =F26+E26
A27: 2 | B27: =Справочник!$B$7 | E27: =Справочник!$C$7 | F27: =G26 | G27: =F27+E27
A28: 3 | B28: =Справочник!$B$8 | E28: =Справочник!$C$8 | F28: =G27 | G28: =F28+E28
A29: 4 | B29: =Справочник!$B$9 | E29: =Справочник!$C$9 | F29: =G28 | G29: =F29+E29
A30: 5 | B30: =Справочник!$B$10 | E30: =Справочник!$C$10 | F30: =G29 | G30: =F30+E30
A31: 6 | B31: =Справочник!$B$11 | E31: =Справочник!$C$11 | F31: =G30 | G31: =F31+E31
A32: 7 | B32: =Справочник!$B$12 | E32: =Справочник!$C$12 | F32: =G31 | G32: =F32+E32
A33: 8 | B33: =Справочник!$B$13 | E33: =Справочник!$C$13 | F33: =G32 | G33: =F33+E33
A35: 4 | B35: Цементная смесь легкая (экспл.колонна) | C35: =Справочник!$C$36 | D35: =Справочник!$H$36 | E35: =SUM(E36:E43) | F35: Этап крепления: Экспл. колонна ОК-245 | H35: =Справочник!$E$28 | I35: =H35-E35 | J35: 46449 | K35: =G43 | L35: =H35-K35 | M35: =IF(L35<0,"СРЫВ ГРАФИКА",IF(L35<14,"РИСК","В ГРАФИКЕ"))
A36: 1 | B36: =Справочник!$B$6 | E36: =Справочник!$C$6 | F36: =J35 | G36: =F36+E36
A37: 2 | B37: =Справочник!$B$7 | E37: =Справочник!$C$7 | F37: =G36 | G37: =F37+E37
A38: 3 | B38: =Справочник!$B$8 | E38: =Справочник!$C$8 | F38: =G37 | G38: =F38+E38
A39: 4 | B39: =Справочник!$B$9 | E39: =Справочник!$C$9 | F39: =G38 | G39: =F39+E39
A40: 5 | B40: =Справочник!$B$10 | E40: =Справочник!$C$10 | F40: =G39 | G40: =F40+E40
A41: 6 | B41: =Справочник!$B$11 | E41: =Справочник!$C$11 | F41: =G40 | G41: =F41+E41
A42: 7 | B42: =Справочник!$B$12 | E42: =Справочник!$C$12 | F42: =G41 | G42: =F42+E42
A43: 8 | B43: =Справочник!$B$13 | E43: =Справочник!$C$13 | F43: =G42 | G43: =F43+E43
A45: 5 | B45: Замедлитель | C45: =Справочник!$C$37 | D45: =Справочник!$H$37 | E45: =SUM(E46:E53) | F45: Этап крепления: Направление ОК-426 | H45: =Справочник!$E$26 | I45: =H45-E45 | J45: 46403 | K45: =G53 | L45: =H45-K45 | M45: =IF(L45<0,"СРЫВ ГРАФИКА",IF(L45<14,"РИСК","В ГРАФИКЕ"))
...

Sheet СВОДНЫЙ ГРАФИК
A1: СВОДНЫЙ ГРАФИК ЗАКУПКИ И ДОСТАВКИ МТР ДЛЯ КРЕПЛЕНИЯ СКВАЖИН ЮГ-1, ЮГ-2, ЮГ-3
A2: Дата формирования 15.09.2026. Вертикальная линия — текущая дата (пересчитывается функцией СЕГОДНЯ при каждом открытии файла). Цвет линии в строке: ЗЕЛЕНАЯ — в графике, ЖЕЛТАЯ — риск, КРАСНАЯ — срыв графика. | K2: ОБЩИЙ СТАТУС: | L2: =IF(COUNTIF(K6:K50,"СРЫВ ГРАФИКА")>0,"СРЫВ ГРАФИКА",IF(COUNTIF(K6:K50,"РИСК")>0,"РИСК","В ГРАФИКЕ"))
A3: ЛЕГЕНДА: | C3: Производственный цикл (заказ, изготовление, затарка) | G3: Транспортное плечо (ж/д, море, доставка на скважину) | K3: Дата потребности МТР на скважине
A4: ПОЗИЦИИ ЗАКУПКИ И ДОСТАВКИ МТР | M4: сен 2026 | AQ4: окт 2026 | BV4: ноя 2026 | CZ4: дек 2026 | EE4: янв 2027 | FJ4: фев 2027 | GL4: мар 2027 | HQ4: апр 2027 | IU4: май 2027 | JZ4: июн 2027
A5: № | B5: Скважина | C5: Наименование МТР | D5: Ед. изм. | E5: Кол-во | F5: Дата начала (план/факт) | G5: Окончание изготовления | H5: Прогноз поставки | I5: ДАТА ПОТРЕБНОСТИ | J5: Запас, сут | K5: СТАТУС | L5: Примечание / компенсирующие мероприятия | M5: 46266 | N5: 46267 | O5: 46268 | P5: 46269 | Q5: 46270 | R5: 46271 | S5: 46272 | T5: 46273 | U5: 46274 | V5: 46275 | W5: 46276 | X5: 46277 | Y5: 46278 | Z5: 46279 | AA5: 46280 | AB5: 46281 | AC5: 46282 | AD5: 46283 | AE5: 46284 | AF5: 46285 | AG5: 46286 | AH5: 46287 | AI5: 46288 | AJ5: 46289 | AK5: 46290 | AL5: 46291 | AM5: 46292 | AN5: 46293 | AO5: 46294 | AP5: 46295 | AQ5: 46296 | AR5: 46297 | AS5: 46298 | AT5: 46299 | AU5: 46300 | AV5: 46301 | AW5: 46302 | AX5: 46303 | AY5: 46304 | AZ5: 46305 | BA5: 46306 | BB5: 46307 | BC5: 46308 | BD5: 46309 | BE5: 46310 | BF5: 46311 | BG5: 46312 | BH5: 46313 | BI5: 46314 | BJ5: 46315 | BK5: 46316 | BL5: 46317 | BM5: 46318 | BN5: 46319 | BO5: 46320 | BP5: 46321 | BQ5: 46322 | BR5: 46323 | BS5: 46324 | BT5: 46325 | BU5: 46326 | BV5: 46327 | BW5: 46328 | BX5: 46329 | BY5: 46330 | BZ5: 46331 | CA5: 46332 | CB5: 46333 | CC5: 46334 | CD5: 46335 | CE5: 46336 | CF5: 46337 | CG5: 46338 | CH5: 46339 | CI5: 46340 | CJ5: 46341 | CK5: 46342 | CL5: 46343 | CM5: 46344 | CN5: 46345 | CO5: 46346 | CP5: 46347 | CQ5: 46348 | CR5: 46349 | CS5: 46350 | CT5: 46351 | CU5: 46352 | CV5: 46353 | CW5: 46354 | CX5: 46355 | CY5: 46356 | CZ5: 46357 | DA5: 46358 | DB5: 46359 | DC5: 46360 | DD5: 46361 | DE5: 46362 | DF5: 46363 | DG5: 46364 | DH5: 46365 | DI5: 46366 | DJ5: 46367 | DK5: 46368 | DL5: 46369 | DM5: 46370 | DN5: 46371 | DO5: 46372 | DP5: 46373 | DQ5: 46374 | DR5: 46375 | DS5: 46376 | DT5: 46377 | DU5: 46378 | DV5: 46379 | DW5: 46380 | DX5: 46381 | DY5: 46382 | DZ5: 46383 | EA5: 46384 | EB5: 46385 | EC5: 46386 | ED5: 46387 | EE5: 46388 | EF5: 46389 | EG5: 46390 | EH5: 46391 | EI5: 46392 | EJ5: 46393 | EK5: 46394 | EL5: 46395 | EM5: 46396 | EN5: 46397 | EO5: 46398 | EP5: 46399 | EQ5: 46400 | ER5: 46401 | ES5: 46402 | ET5: 46403 | EU5: 46404 | EV5: 46405 | EW5: 46406 | EX5: 46407 | EY5: 46408 | EZ5: 46409 | FA5: 46410 | FB5: 46411 | FC5: 46412 | FD5: 46413 | FE5: 46414 | FF5: 46415 | FG5: 46416 | FH5: 46417 | FI5: 46418 | FJ5: 46419 | FK5: 46420 | FL5: 46421 | FM5: 46422 | FN5: 46423 | FO5: 46424 | FP5: 46425 | FQ5: 46426 | FR5: 46427 | FS5: 46428 | FT5: 46429 | FU5: 46430 | FV5: 46431 | FW5: 46432 | FX5: 46433 | FY5: 46434 | FZ5: 46435 | GA5: 46436 | GB5: 46437 | GC5: 46438 | GD5: 46439 | GE5: 46440 | GF5: 46441 | GG5: 46442 | GH5: 46443 | GI5: 46444 | GJ5: 46445 | GK5: 46446 | GL5: 46447 | GM5: 46448 | GN5: 46449 | GO5: 46450 | GP5: 46451 | GQ5: 46452 | GR5: 46453 | GS5: 46454 | GT5: 46455 | GU5: 46456 | GV5: 46457 | GW5: 46458 | GX5: 46459 | GY5: 46460 | GZ5: 46461 | HA5: 46462 | HB5: 46463 | HC5: 46464 | HD5: 46465 | HE5: 46466 | HF5: 46467 | HG5: 46468 | HH5: 46469 | HI5: 46470 | HJ5: 46471 | HK5: 46472 | HL5: 46473 | HM5: 46474 | HN5: 46475 | HO5: 46476 | HP5: 46477 | HQ5: 46478 | HR5: 46479 | HS5: 46480 | HT5: 46481 | HU5: 46482 | HV5: 46483 | HW5: 46484 | HX5: 46485 | HY5: 46486 | HZ5: 46487 | IA5: 46488 | IB5: 46489 | IC5: 46490 | ID5: 46491 | IE5: 46492 | IF5: 46493 | IG5: 46494 | IH5: 46495 | II5: 46496 | IJ5: 46497 | IK5: 46498 | IL5: 46499 | IM5: 46500 | IN5: 46501 | IO5: 46502 | IP5: 46503 | IQ5: 46504 | IR5: 46505 | IS5: 46506 | IT5: 46507 | IU5: 46508 | IV5: 46509 | IW5: 46510 | IX5: 46511 | IY5: 46512 | IZ5: 46513 | JA5: 46514 | JB5: 46515 | JC5: 46516 | JD5: 46517 | JE5: 46518 | JF5: 46519 | JG5: 46520 | JH5: 46521 | JI5: 46522 | JJ5: 46523 | JK5: 46524 | JL5: 46525 | JM5: 46526 | JN5: 46527 | JO5: 46528 | JP5: 46529 | JQ5: 46530 | JR5: 46531 | JS5: 46532 | JT5: 46533 | JU5: 46534 | JV5: 46535 | JW5: 46536 | JX5: 46537 | JY5: 46538 | JZ5: 46539 | KA5: 46540 | KB5: 46541 | KC5: 46542 | KD5: 46543 | KE5: 46544 | KF5: 46545 | KG5: 46546 | KH5: 46547 | KI5: 46548 | KJ5: 46549 | KK5: 46550 | KL5: 46551 | KM5: 46552 | KN5: 46553 | KO5: 46554 | KP5: 46555 | KQ5: 46556 | KR5: 46557 | KS5: 46558 | KT5: 46559 | KU5: 46560 | KV5: 46561 | KW5: 46562 | KX5: 46563 | KY5: 46564 | KZ5: 46565 | LA5: 46566 | LB5: 46567 | LC5: 46568
A6: СКВАЖИНА ЮГ-1
A7: 1 | B7: ЮГ-1 | C7: ='ЮГ-1'!B5 | D7: ='ЮГ-1'!C5 | E7: ='ЮГ-1'!D5 | F7: ='ЮГ-1'!J5 | G7: ='ЮГ-1'!G8 | H7: ='ЮГ-1'!K5 | I7: ='ЮГ-1'!H5 | J7: ='ЮГ-1'!L5 | K7: ='ЮГ-1'!M5 | L7: ='ЮГ-1'!N5
A8: 2 | B8: ЮГ-1 | C8: ='ЮГ-1'!B15 | D8: ='ЮГ-1'!C15 | E8: ='ЮГ-1'!D15 | F8: ='ЮГ-1'!J15 | G8: ='ЮГ-1'!G18 | H8: ='ЮГ-1'!K15 | I8: ='ЮГ-1'!H15 | J8: ='ЮГ-1'!L15 | K8: ='ЮГ-1'!M15 | L8: ='ЮГ-1'!N15
A9: 3 | B9: ЮГ-1 | C9: ='ЮГ-1'!B25 | D9: ='ЮГ-1'!C25 | E9: ='ЮГ-1'!D25 | F9: ='ЮГ-1'!J25 | G9: ='ЮГ-1'!G28 | H9: ='ЮГ-1'!K25 | I9: ='ЮГ-1'!H25 | J9: ='ЮГ-1'!L25 | K9: ='ЮГ-1'!M25 | L9: ='ЮГ-1'!N25
A10: 4 | B10: ЮГ-1 | C10: ='ЮГ-1'!B35 | D10: ='ЮГ-1'!C35 | E10: ='ЮГ-1'!D35 | F10: ='ЮГ-1'!J35 | G10: ='ЮГ-1'!G38 | H10: ='ЮГ-1'!K35 | I10: ='ЮГ-1'!H35 | J10: ='ЮГ-1'!L35 | K10: ='ЮГ-1'!M35 | L10: ='ЮГ-1'!N35
A11: 5 | B11: ЮГ-1 | C11: ='ЮГ-1'!B45 | D11: ='ЮГ-1'!C45 | E11: ='ЮГ-1'!D45 | F11: ='ЮГ-1'!J45 | G11: ='ЮГ-1'!G48 | H11: ='ЮГ-1'!K45 | I11: ='ЮГ-1'!H45 | J11: ='ЮГ-1'!L45 | K11: ='ЮГ-1'!M45 | L11: ='ЮГ-1'!N45
A12: 6 | B12: ЮГ-1 | C12: ='ЮГ-1'!B55 | D12: ='ЮГ-1'!C55 | E12: ='ЮГ-1'!D55 | F12: ='ЮГ-1'!J55 | G12: ='ЮГ-1'!G58 | H12: ='ЮГ-1'!K55 | I12: ='ЮГ-1'!H55 | J12: ='ЮГ-1'!L55 | K12: ='ЮГ-1'!M55 | L12: ='ЮГ-1'!N55
A13: 7 | B13: ЮГ-1 | C13: ='ЮГ-1'!B65 | D13: ='ЮГ-1'!C65 | E13: ='ЮГ-1'!D65 | F13: ='ЮГ-1'!J65 | G13: ='ЮГ-1'!G68 | H13: ='ЮГ-1'!K65 | I13: ='ЮГ-1'!H65 | J13: ='ЮГ-1'!L65 | K13: ='ЮГ-1'!M65 | L13: ='ЮГ-1'!N65
A14: 8 | B14: ЮГ-1 | C14: ='ЮГ-1'!B75 | D14: ='ЮГ-1'!C75 | E14: ='ЮГ-1'!D75 | F14: ='ЮГ-1'!J75 | G14: ='ЮГ-1'!G78 | H14: ='ЮГ-1'!K75 | I14: ='ЮГ-1'!H75 | J14: ='ЮГ-1'!L75 | K14: ='ЮГ-1'!M75 | L14: ='ЮГ-1'!N75
A15: 9 | B15: ЮГ-1 | C15: ='ЮГ-1'!B85 | D15: ='ЮГ-1'!C85 | E15: ='ЮГ-1'!D85 | F15: ='ЮГ-1'!J85 | G15: ='ЮГ-1'!G88 | H15: ='ЮГ-1'!K85 | I15: ='ЮГ-1'!H85 | J15: ='ЮГ-1'!L85 | K15: ='ЮГ-1'!M85 | L15: ='ЮГ-1'!N85
A16: 10 | B16: ЮГ-1 | C16: ='ЮГ-1'!B95 | D16: ='ЮГ-1'!C95 | E16: ='ЮГ-1'!D95 | F16: ='ЮГ-1'!J95 | G16: ='ЮГ-1'!G98 | H16: ='ЮГ-1'!K95 | I16: ='ЮГ-1'!H95 | J16: ='ЮГ-1'!L95 | K16: ='ЮГ-1'!M95 | L16: ='ЮГ-1'!N95
A17: 11 | B17: ЮГ-1 | C17: ='ЮГ-1'!B105 | D17: ='ЮГ-1'!C105 | E17: ='ЮГ-1'!D105 | F17: ='ЮГ-1'!J105 | G17: ='ЮГ-1'!G108 | H17: ='ЮГ-1'!K105 | I17: ='ЮГ-1'!H105 | J17: ='ЮГ-1'!L105 | K17: ='ЮГ-1'!M105 | L17: ='ЮГ-1'!N105
A18: 12 | B18: ЮГ-1 | C18: ='ЮГ-1'!B115 | D18: ='ЮГ-1'!C115 | E18: ='ЮГ-1'!D115 | F18: ='ЮГ-1'!J115 | G18: ='ЮГ-1'!G118 | H18: ='ЮГ-1'!K115 | I18: ='ЮГ-1'!H115 | J18: ='ЮГ-1'!L115 | K18: ='ЮГ-1'!M115 | L18: ='ЮГ-1'!N115
A19: 13 | B19: ЮГ-1 | C19: ='ЮГ-1'!B125 | D19: ='ЮГ-1'!C125 | E19: ='ЮГ-1'!D125 | F19: ='ЮГ-1'!J125 | G19: ='ЮГ-1'!G128 | H19: ='ЮГ-1'!K125 | I19: ='ЮГ-1'!H125 | J19: ='ЮГ-1'!L125 | K19: ='ЮГ-1'!M125 | L19: ='ЮГ-1'!N125
A20: 14 | B20: ЮГ-1 | C20: ='ЮГ-1'!B135 | D20: ='ЮГ-1'!C135 | E20: ='ЮГ-1'!D135 | F20: ='ЮГ-1'!J135 | G20: ='ЮГ-1'!G138 | H20: ='ЮГ-1'!K135 | I20: ='ЮГ-1'!H135 | J20: ='ЮГ-1'!L135 | K20: ='ЮГ-1'!M135 | L20: ='ЮГ-1'!N135
A21: СКВАЖИНА ЮГ-2
A22: 15 | B22: ЮГ-2 | C22: ='ЮГ-2'!B5 | D22: ='ЮГ-2'!C5 | E22: ='ЮГ-2'!D5 | F22: ='ЮГ-2'!J5 | G22: ='ЮГ-2'!G8 | H22: ='ЮГ-2'!K5 | I22: ='ЮГ-2'!H5 | J22: ='ЮГ-2'!L5 | K22: ='ЮГ-2'!M5 | L22: ='ЮГ-2'!N5
A23: 16 | B23: ЮГ-2 | C23: ='ЮГ-2'!B15 | D23: ='ЮГ-2'!C15 | E23: ='ЮГ-2'!D15 | F23: ='ЮГ-2'!J15 | G23: ='ЮГ-2'!G18 | H23: ='ЮГ-2'!K15 | I23: ='ЮГ-2'!H15 | J23: ='ЮГ-2'!L15 | K23: ='ЮГ-2'!M15 | L23: ='ЮГ-2'!N15
A24: 17 | B24: ЮГ-2 | C24: ='ЮГ-2'!B25 | D24: ='ЮГ-2'!C25 | E24: ='ЮГ-2'!D25 | F24: ='ЮГ-2'!J25 | G24: ='ЮГ-2'!G28 | H24: ='ЮГ-2'!K25 | I24: ='ЮГ-2'!H25 | J24: ='ЮГ-2'!L25 | K24: ='ЮГ-2'!M25 | L24: ='ЮГ-2'!N25
A25: 18 | B25: ЮГ-2 | C25: ='ЮГ-2'!B35 | D25: ='ЮГ-2'!C35 | E25: ='ЮГ-2'!D35 | F25: ='ЮГ-2'!J35 | G25: ='ЮГ-2'!G38 | H25: ='ЮГ-2'!K35 | I25: ='ЮГ-2'!H35 | J25: ='ЮГ-2'!L35 | K25: ='ЮГ-2'!M35 | L25: ='ЮГ-2'!N35
A26: 19 | B26: ЮГ-2 | C26: ='ЮГ-2'!B45 | D26: ='ЮГ-2'!C45 | E26: ='ЮГ-2'!D45 | F26: ='ЮГ-2'!J45 | G26: ='ЮГ-2'!G48 | H26: ='ЮГ-2'!K45 | I26: ='ЮГ-2'!H45 | J26: ='ЮГ-2'!L45 | K26: ='ЮГ-2'!M45 | L26: ='ЮГ-2'!N45
A27: 20 | B27: ЮГ-2 | C27: ='ЮГ-2'!B55 | D27: ='ЮГ-2'!C55 | E27: ='ЮГ-2'!D55 | F27: ='ЮГ-2'!J55 | G27: ='ЮГ-2'!G58 | H27: ='ЮГ-2'!K55 | I27: ='ЮГ-2'!H55 | J27: ='ЮГ-2'!L55 | K27: ='ЮГ-2'!M55 | L27: ='ЮГ-2'!N55
A28: 21 | B28: ЮГ-2 | C28: ='ЮГ-2'!B65 | D28: ='ЮГ-2'!C65 | E28: ='ЮГ-2'!D65 | F28: ='ЮГ-2'!J65 | G28: ='ЮГ-2'!G68 | H28: ='ЮГ-2'!K65 | I28: ='ЮГ-2'!H65 | J28: ='ЮГ-2'!L65 | K28: ='ЮГ-2'!M65 | L28: ='ЮГ-2'!N65
A29: 22 | B29: ЮГ-2 | C29: ='ЮГ-2'!B75 | D29: ='ЮГ-2'!C75 | E29: ='ЮГ-2'!D75 | F29: ='ЮГ-2'!J75 | G29: ='ЮГ-2'!G78 | H29: ='ЮГ-2'!K75 | I29: ='ЮГ-2'!H75 | J29: ='ЮГ-2'!L75 | K29: ='ЮГ-2'!M75 | L29: ='ЮГ-2'!N75
A30: 23 | B30: ЮГ-2 | C30: ='ЮГ-2'!B85 | D30: ='ЮГ-2'!C85 | E30: ='ЮГ-2'!D85 | F30: ='ЮГ-2'!J85 | G30: ='ЮГ-2'!G88 | H30: ='ЮГ-2'!K85 | I30: ='ЮГ-2'!H85 | J30: ='ЮГ-2'!L85 | K30: ='ЮГ-2'!M85 | L30: ='ЮГ-2'!N85
A31: 24 | B31: ЮГ-2 | C31: ='ЮГ-2'!B95 | D31: ='ЮГ-2'!C95 | E31: ='ЮГ-2'!D95 | F31: ='ЮГ-2'!J95 | G31: ='ЮГ-2'!G98 | H31: ='ЮГ-2'!K95 | I31: ='ЮГ-2'!H95 | J31: ='ЮГ-2'!L95 | K31: ='ЮГ-2'!M95 | L31: ='ЮГ-2'!N95
A32: 25 | B32: ЮГ-2 | C32: ='ЮГ-2'!B105 | D32: ='ЮГ-2'!C105 | E32: ='ЮГ-2'!D105 | F32: ='ЮГ-2'!J105 | G32: ='ЮГ-2'!G108 | H32: ='ЮГ-2'!K105 | I32: ='ЮГ-2'!H105 | J32: ='ЮГ-2'!L105 | K32: ='ЮГ-2'!M105 | L32: ='ЮГ-2'!N105
A33: 26 | B33: ЮГ-2 | C33: ='ЮГ-2'!B115 | D33: ='ЮГ-2'!C115 | E33: ='ЮГ-2'!D115 | F33: ='ЮГ-2'!J115 | G33: ='ЮГ-2'!G118 | H33: ='ЮГ-2'!K115 | I33: ='ЮГ-2'!H115 | J33: ='ЮГ-2'!L115 | K33: ='ЮГ-2'!M115 | L33: ='ЮГ-2'!N115
A34: 27 | B34: ЮГ-2 | C34: ='ЮГ-2'!B125 | D34: ='ЮГ-2'!C125 | E34: ='ЮГ-2'!D125 | F34: ='ЮГ-2'!J125 | G34: ='ЮГ-2'!G128 | H34: ='ЮГ-2'!K125 | I34: ='ЮГ-2'!H125 | J34: ='ЮГ-2'!L125 | K34: ='ЮГ-2'!M125 | L34: ='ЮГ-2'!N125
A35: 28 | B35: ЮГ-2 | C35: ='ЮГ-2'!B135 | D35: ='ЮГ-2'!C135 | E35: ='ЮГ-2'!D135 | F35: ='ЮГ-2'!J135 | G35: ='ЮГ-2'!G138 | H35: ='ЮГ-2'!K135 | I35: ='ЮГ-2'!H135 | J35: ='ЮГ-2'!L135 | K35: ='ЮГ-2'!M135 | L35: ='ЮГ-2'!N135
A36: СКВАЖИНА ЮГ-3
A37: 29 | B37: ЮГ-3 | C37: ='ЮГ-3'!B5 | D37: ='ЮГ-3'!C5 | E37: ='ЮГ-3'!D5 | F37: ='ЮГ-3'!J5 | G37: ='ЮГ-3'!G8 | H37: ='ЮГ-3'!K5 | I37: ='ЮГ-3'!H5 | J37: ='ЮГ-3'!L5 | K37: ='ЮГ-3'!M5 | L37: ='ЮГ-3'!N5
A38: 30 | B38: ЮГ-3 | C38: ='ЮГ-3'!B15 | D38: ='ЮГ-3'!C15 | E38: ='ЮГ-3'!D15 | F38: ='ЮГ-3'!J15 | G38: ='ЮГ-3'!G18 | H38: ='ЮГ-3'!K15 | I38: ='ЮГ-3'!H15 | J38: ='ЮГ-3'!L15 | K38: ='ЮГ-3'!M15 | L38: ='ЮГ-3'!N15
A39: 31 | B39: ЮГ-3 | C39: ='ЮГ-3'!B25 | D39: ='ЮГ-3'!C25 | E39: ='ЮГ-3'!D25 | F39: ='ЮГ-3'!J25 | G39: ='ЮГ-3'!G28 | H39: ='ЮГ-3'!K25 | I39: ='ЮГ-3'!H25 | J39: ='ЮГ-3'!L25 | K39: ='ЮГ-3'!M25 | L39: ='ЮГ-3'!N25
A40: 32 | B40: ЮГ-3 | C40: ='ЮГ-3'!B35 | D40: ='ЮГ-3'!C35 | E40: ='ЮГ-3'!D35 | F40: ='ЮГ-3'!J35 | G40: ='ЮГ-3'!G38 | H40: ='ЮГ-3'!K35 | I40: ='ЮГ-3'!H35 | J40: ='ЮГ-3'!L35 | K40: ='ЮГ-3'!M35 | L40: ='ЮГ-3'!N35
...

Sheet Сводная потребность
A1: СВОДНАЯ ПОТРЕБНОСТЬ В МТР НА КРЕПЛЕНИЕ СКВАЖИН ЮГ-1, ЮГ-2, ЮГ-3
A2: Объем закупки по номенклатуре в целом по программе. Статус — худший из трех скважин.
A4: № | B4: Наименование МТР | C4: Ед. изм. | D4: ЮГ-1 | E4: ЮГ-2 | F4: ЮГ-3 | G4: ИТОГО к закупке | H4: Цикл поставки, сут | I4: Самая ранняя потребность | J4: Мин. запас, сут | K4: ХУДШИЙ СТАТУС
A5: 1 | B5: =Справочник!B33 | C5: =Справочник!C33 | D5: ='ЮГ-1'!D5 | E5: ='ЮГ-2'!D5 | F5: ='ЮГ-3'!D5 | G5: =SUM(D5:F5) | H5: ='ЮГ-1'!E5 | I5: =MIN('ЮГ-1'!H5,'ЮГ-2'!H5,'ЮГ-3'!H5) | J5: =MIN('ЮГ-1'!L5,'ЮГ-2'!L5,'ЮГ-3'!L5) | K5: =IF(J5<0,"СРЫВ ГРАФИКА",IF(J5<14,"РИСК","В ГРАФИКЕ"))
A6: 2 | B6: =Справочник!B34 | C6: =Справочник!C34 | D6: ='ЮГ-1'!D15 | E6: ='ЮГ-2'!D15 | F6: ='ЮГ-3'!D15 | G6: =SUM(D6:F6) | H6: ='ЮГ-1'!E15 | I6: =MIN('ЮГ-1'!H15,'ЮГ-2'!H15,'ЮГ-3'!H15) | J6: =MIN('ЮГ-1'!L15,'ЮГ-2'!L15,'ЮГ-3'!L15) | K6: =IF(J6<0,"СРЫВ ГРАФИКА",IF(J6<14,"РИСК","В ГРАФИКЕ"))
A7: 3 | B7: =Справочник!B35 | C7: =Справочник!C35 | D7: ='ЮГ-1'!D25 | E7: ='ЮГ-2'!D25 | F7: ='ЮГ-3'!D25 | G7: =SUM(D7:F7) | H7: ='ЮГ-1'!E25 | I7: =MIN('ЮГ-1'!H25,'ЮГ-2'!H25,'ЮГ-3'!H25) | J7: =MIN('ЮГ-1'!L25,'ЮГ-2'!L25,'ЮГ-3'!L25) | K7: =IF(J7<0,"СРЫВ ГРАФИКА",IF(J7<14,"РИСК","В ГРАФИКЕ"))
A8: 4 | B8: =Справочник!B36 | C8: =Справочник!C36 | D8: ='ЮГ-1'!D35 | E8: ='ЮГ-2'!D35 | F8: ='ЮГ-3'!D35 | G8: =SUM(D8:F8) | H8: ='ЮГ-1'!E35 | I8: =MIN('ЮГ-1'!H35,'ЮГ-2'!H35,'ЮГ-3'!H35) | J8: =MIN('ЮГ-1'!L35,'ЮГ-2'!L35,'ЮГ-3'!L35) | K8: =IF(J8<0,"СРЫВ ГРАФИКА",IF(J8<14,"РИСК","В ГРАФИКЕ"))
A9: 5 | B9: =Справочник!B37 | C9: =Справочник!C37 | D9: ='ЮГ-1'!D45 | E9: ='ЮГ-2'!D45 | F9: ='ЮГ-3'!D45 | G9: =SUM(D9:F9) | H9: ='ЮГ-1'!E45 | I9: =MIN('ЮГ-1'!H45,'ЮГ-2'!H45,'ЮГ-3'!H45) | J9: =MIN('ЮГ-1'!L45,'ЮГ-2'!L45,'ЮГ-3'!L45) | K9: =IF(J9<0,"СРЫВ ГРАФИКА",IF(J9<14,"РИСК","В ГРАФИКЕ"))
A10: 6 | B10: =Справочник!B38 | C10: =Справочник!C38 | D10: ='ЮГ-1'!D55 | E10: ='ЮГ-2'!D55 | F10: ='ЮГ-3'!D55 | G10: =SUM(D10:F10) | H10: ='ЮГ-1'!E55 | I10: =MIN('ЮГ-1'!H55,'ЮГ-2'!H55,'ЮГ-3'!H55) | J10: =MIN('ЮГ-1'!L55,'ЮГ-2'!L55,'ЮГ-3'!L55) | K10: =IF(J10<0,"СРЫВ ГРАФИКА",IF(J10<14,"РИСК","В ГРАФИКЕ"))
A11: 7 | B11: =Справочник!B39 | C11: =Справочник!C39 | D11: ='ЮГ-1'!D65 | E11: ='ЮГ-2'!D65 | F11: ='ЮГ-3'!D65 | G11: =SUM(D11:F11) | H11: ='ЮГ-1'!E65 | I11: =MIN('ЮГ-1'!H65,'ЮГ-2'!H65,'ЮГ-3'!H65) | J11: =MIN('ЮГ-1'!L65,'ЮГ-2'!L65,'ЮГ-3'!L65) | K11: =IF(J11<0,"СРЫВ ГРАФИКА",IF(J11<14,"РИСК","В ГРАФИКЕ"))
A12: 8 | B12: =Справочник!B40 | C12: =Справочник!C40 | D12: ='ЮГ-1'!D75 | E12: ='ЮГ-2'!D75 | F12: ='ЮГ-3'!D75 | G12: =SUM(D12:F12) | H12: ='ЮГ-1'!E75 | I12: =MIN('ЮГ-1'!H75,'ЮГ-2'!H75,'ЮГ-3'!H75) | J12: =MIN('ЮГ-1'!L75,'ЮГ-2'!L75,'ЮГ-3'!L75) | K12: =IF(J12<0,"СРЫВ ГРАФИКА",IF(J12<14,"РИСК","В ГРАФИКЕ"))
A13: 9 | B13: =Справочник!B41 | C13: =Справочник!C41 | D13: ='ЮГ-1'!D85 | E13: ='ЮГ-2'!D85 | F13: ='ЮГ-3'!D85 | G13: =SUM(D13:F13) | H13: ='ЮГ-1'!E85 | I13: =MIN('ЮГ-1'!H85,'ЮГ-2'!H85,'ЮГ-3'!H85) | J13: =MIN('ЮГ-1'!L85,'ЮГ-2'!L85,'ЮГ-3'!L85) | K13: =IF(J13<0,"СРЫВ ГРАФИКА",IF(J13<14,"РИСК","В ГРАФИКЕ"))
A14: 10 | B14: =Справочник!B42 | C14: =Справочник!C42 | D14: ='ЮГ-1'!D95 | E14: ='ЮГ-2'!D95 | F14: ='ЮГ-3'!D95 | G14: =SUM(D14:F14) | H14: ='ЮГ-1'!E95 | I14: =MIN('ЮГ-1'!H95,'ЮГ-2'!H95,'ЮГ-3'!H95) | J14: =MIN('ЮГ-1'!L95,'ЮГ-2'!L95,'ЮГ-3'!L95) | K14: =IF(J14<0,"СРЫВ ГРАФИКА",IF(J14<14,"РИСК","В ГРАФИКЕ"))
A15: 11 | B15: =Справочник!B43 | C15: =Справочник!C43 | D15: ='ЮГ-1'!D105 | E15: ='ЮГ-2'!D105 | F15: ='ЮГ-3'!D105 | G15: =SUM(D15:F15) | H15: ='ЮГ-1'!E105 | I15: =MIN('ЮГ-1'!H105,'ЮГ-2'!H105,'ЮГ-3'!H105) | J15: =MIN('ЮГ-1'!L105,'ЮГ-2'!L105,'ЮГ-3'!L105) | K15: =IF(J15<0,"СРЫВ ГРАФИКА",IF(J15<14,"РИСК","В ГРАФИКЕ"))
A16: 12 | B16: =Справочник!B44 | C16: =Справочник!C44 | D16: ='ЮГ-1'!D115 | E16: ='ЮГ-2'!D115 | F16: ='ЮГ-3'!D115 | G16: =SUM(D16:F16) | H16: ='ЮГ-1'!E115 | I16: =MIN('ЮГ-1'!H115,'ЮГ-2'!H115,'ЮГ-3'!H115) | J16: =MIN('ЮГ-1'!L115,'ЮГ-2'!L115,'ЮГ-3'!L115) | K16: =IF(J16<0,"СРЫВ ГРАФИКА",IF(J16<14,"РИСК","В ГРАФИКЕ"))
A17: 13 | B17: =Справочник!B45 | C17: =Справочник!C45 | D17: ='ЮГ-1'!D125 | E17: ='ЮГ-2'!D125 | F17: ='ЮГ-3'!D125 | G17: =SUM(D17:F17) | H17: ='ЮГ-1'!E125 | I17: =MIN('ЮГ-1'!H125,'ЮГ-2'!H125,'ЮГ-3'!H125) | J17: =MIN('ЮГ-1'!L125,'ЮГ-2'!L125,'ЮГ-3'!L125) | K17: =IF(J17<0,"СРЫВ ГРАФИКА",IF(J17<14,"РИСК","В ГРАФИКЕ"))
A18: 14 | B18: =Справочник!B46 | C18: =Справочник!C46 | D18: ='ЮГ-1'!D135 | E18: ='ЮГ-2'!D135 | F18: ='ЮГ-3'!D135 | G18: =SUM(D18:F18) | H18: ='ЮГ-1'!E135 | I18: =MIN('ЮГ-1'!H135,'ЮГ-2'!H135,'ЮГ-3'!H135) | J18: =MIN('ЮГ-1'!L135,'ЮГ-2'!L135,'ЮГ-3'!L135) | K18: =IF(J18<0,"СРЫВ ГРАФИКА",IF(J18<14,"РИСК","В ГРАФИКЕ"))
